<?xml version="1.0"?>
<robot name="custom_robot" xmlns:xacro="http://www.ros.org/wiki/xacro">
    <xacro:include filename="$(find custom_robot)/urdf/custom_robot.gazebo"/>
    <link name="base"></link>
    <joint name="base_joint" type="fixed">
        <origin xyz="0.0 0.0 0.0" rpy="0.0 0.0 0.0"/>
        <parent link="base"/>
        <child link="base_plate"/>
    </joint>

    <link name="base_plate">
        <pose> 0 0 0.1 0 0 0 </pose>
        <origin xyz="0.0 0.0 0.0" rpy="0.0 0.0 0.0"/>                    
        <inertial>
            <origin xyz="0.0 0.0 0.0" rpy="0.0 0.0 0.0"/>
            <mass value="0.0"/>
            <inertia ixx="0.0" ixy="0.0" ixz="0.0" iyy="0.0" iyz="0.0" izz="0.0"/>
        </inertial>
        <visual name="base_plate_visual">
            <geometry>
                <mesh filename="package://custom_robot/meshes/BasePlate.dae"/>
            </geometry>
        </visual>
        <collision>
            <origin xyz="0.0 0.0 0.0" rpy="0.0 0.0 0.0"/>
            <geometry>
                <box size="0.0 0.0 0.0"/>
            </geometry>
        </collision>
    </link>
	
	<link name="right_wheel_hub">
		<inertial>
			<origin xyz="0.0 -0.25 0.0" rpy="0.0 0.0 0.0"/>
			<mass value="0.0"/>
			<inertia ixx="0.0" ixy="0.0" ixz="0.0" iyy="0.0" iyz="0.0" izz="0.0"/>
		</inertial>
		<visual name="right_wheel_hub_visual">
			<origin xyz="0.0 -0.25 0.0" rpy="0.0 0.0 0.0"/>
			<geometry>
				<mesh filename="package://custom_robot/meshes/BearingMount.dae"/>
			</geometry>
		</visual>
		<collision name="right_wheel_hub_collision">
			<origin xyz="0.0 -0.25 0.0" rpy="0.0 0.0 0.0"/>
			<geometry>
				<cylinder radius="0.150" length="0.010"/>
			</geometry>
		</collision>
	</link>
	<joint name="right_wheel_hub_joint" type="fixed">
		<origin xyz="0.0 0.0 0.0" rpy="0.0 0.0 0.0"/>
		<parent link="base_plate"/>
		<child link="right_wheel_hub"/>
        <axis xyz="0.0 0.0 0.0"/>
	</joint>
	
	<link name="left_wheel_hub">
		<inertial>
			<origin xyz="0.0 0.25 0.0" rpy="0.0 0.0 0.0"/>
			<mass value="0.0"/>
			<inertia ixx="0.0" ixy="0.0" ixz="0.0" iyy="0.0" iyz="0.0" izz="0.0"/>
		</inertial>
		<visual name="left_wheel_hub_visual">
			<origin xyz="0.0 0.25 0.0" rpy="0.0 0.0 0.0"/>
			<geometry>
				<mesh filename="package://custom_robot/meshes/BearingMount.dae"/>
			</geometry>
		</visual>
		<collision name="left_wheel_hub_collision">
			<origin xyz="0.0 0.25 0.0" rpy="0.0 0.0 0.0"/>
			<geometry>
				<cylinder radius="0.150" length="0.010"/>
			</geometry>
		</collision>
	</link>
	<joint name="left_wheel_hub_joint" type="fixed">
		<origin xyz="0.0 0.0 0.0" rpy="0.0 0.0 0.0"/>
		<parent link="base_plate"/>
		<child link="left_wheel_hub"/>
        <axis xyz="0.0 0.0 0.0"/>
	</joint>

	<link name="left_wheel_bearing">
		<inertial>
			<origin xyz="0.0  0.30 0.0" rpy="0.0 0.0 1.57"/>
			<mass value="0.0"/>
			<inertia ixx="0.0" ixy="0.0" ixz="0.0" iyy="0.0" iyz="0.0" izz="0.0"/>
		</inertial>
		<visual name="left_wheel_bearing_visual">
			<origin xyz="0.0  0.30 0.0" rpy="0.0 0.0 1.57"/>
			<geometry>
				<mesh filename="package://custom_robot/meshes/WheelBearing.dae"/>
			</geometry>
		</visual>
		<collision name="left_wheel_bearing_collision">
			<origin xyz="0.0  0.30 0.0" rpy="0.0 0.0 1.57"/>
			<geometry>
				<cylinder radius="0.150" length="0.010"/>
			</geometry>
		</collision>
	</link>
	<joint name="left_wheel_bearing_joint" type="fixed">
		<origin xyz="0.0 0.0 0.0" rpy="0.0 0.0 0.0"/>
		<parent link="left_wheel_hub"/>
		<child link="left_wheel_bearing"/>
        <axis xyz="0.0 0.0 0.0"/>
	</joint>

	<link name="right_wheel_bearing">
		<inertial>
			<origin xyz="0.0 -0.30 0.0" rpy="0.0 0.0 1.57"/>
			<mass value="0.0"/>
			<inertia ixx="0.0" ixy="0.0" ixz="0.0" iyy="0.0" iyz="0.0" izz="0.0"/>
		</inertial>
		<visual name="left_wheel_bearing_visual">
			<origin xyz="0.0 -0.30 0.0" rpy="0.0 0.0 1.57"/>
			<geometry>
				<mesh filename="package://custom_robot/meshes/WheelBearing.dae"/>
			</geometry>
		</visual>
		<collision name="right_wheel_bearing_collision">
			<origin xyz="0.0 -0.30 0.0" rpy="0.0 0.0 1.57"/>
			<geometry>
				<cylinder radius="0.150" length="0.010"/>
			</geometry>
		</collision>
	</link>
	<joint name="right_wheel_bearing_joint" type="fixed">
		<origin xyz="0.0 0.0 0.0" rpy="0.0 0.0 0.0"/>
		<parent link="right_wheel_hub"/>
		<child link="right_wheel_bearing"/>
        <axis xyz="0.0 0.0 0.0"/>
	</joint>
	
	<link name="right_wheel_shaft">
		<inertial>
			<origin xyz="0.0 -0.35 0.0" rpy="0.0 0.0 1.57"/>
			<mass value="0.0"/>
			<inertia ixx="0.0" ixy="0.0" ixz="0.0" iyy="0.0" iyz="0.0" izz="0.0"/>
		</inertial>
		<visual name="right_wheel_shaft_visual">
			<origin xyz="0.0 -0.35 0.0" rpy="0.0 0.0 1.57"/>
			<geometry>
				<mesh filename="package://custom_robot/meshes/WheelShaft.dae"/>
			</geometry>
		</visual>
		<collision name="right_wheel_shaft_collision">
			<origin xyz="0.0 -0.35 0.0" rpy="0.0 0.0 1.57"/>
			<geometry>
				<cylinder radius="0.150" length="0.010"/>
			</geometry>
		</collision>
	</link>
	<joint name="right_wheel_shaft_joint" type="continuous">
		<origin xyz="0.0 0.0 0.0" rpy="0.0 0.0 0.0"/>
		<parent link="right_wheel_bearing"/>
		<child link="right_wheel_shaft"/>
        <axis xyz="0.0 1 0.0" rpy="0.0 0.0 0.0"/>
        <limit effort="10000" velocity="1000"/>
        <dynamics damping="1.0" friction="1.0"/>
	</joint>

	<link name="right_wheel">
		<inertial>
			<origin xyz="0.0 -0.5 0.0" rpy="0.0 0.0 0.0"/>
			<mass value="0.0"/>
			<inertia ixx="0.0" ixy="0.0" ixz="0.0" iyy="0.0" iyz="0.0" izz="0.0"/>
		</inertial>
		<visual name="right_wheel_visual">
			<origin xyz="0.0 -0.5 0.0" rpy="0.0 0.0 0.0"/>
			<geometry>
				<mesh filename="package://custom_robot/meshes/Wheel.dae"/>
			</geometry>
		</visual>
		<collision name="right_wheel_collision">
			<origin xyz="0.0 -0.5 0.0" rpy="0.0 0.0 0.0"/>
			<geometry>
				<cylinder radius="150" length="10.0"/>
			</geometry>
		</collision>
	</link>
	<joint name="right_wheel_joint" type="fixed">
		<origin xyz="0.0 0.0 0.0" rpy="0.0 0.0 0.0"/>
		<parent link="right_wheel_shaft"/>
		<child link="right_wheel"/>
	</joint>
	
	<link name="left_wheel_shaft">
		<inertial>
			<origin xyz="0.0  0.35 0.0" rpy="0.0 0.0 -1.57"/>
			<mass value="0.0"/>
			<inertia ixx="0.0" ixy="0.0" ixz="0.0" iyy="0.0" iyz="0.0" izz="0.0"/>
		</inertial>
		<visual name="left_wheel_shaft_visual">
			<origin xyz="0.0  0.35 0.0" rpy="0.0 0.0 -1.57"/>
			<geometry>
				<mesh filename="package://custom_robot/meshes/WheelShaft.dae"/>
			</geometry>
		</visual>
		<collision name="left_wheel_shaft_collision">
			<origin xyz="0.0  0.35 0.0" rpy="0.0 0.0 -1.57"/>
			<geometry>
				<cylinder radius="0.150" length="0.010"/>
			</geometry>
		</collision>
	</link>
	<joint name="left_wheel_shaft_joint" type="continuous">
		<origin xyz="0.0 0.0 0.0" rpy="0.0 0.0 0.0"/>
		<parent link="left_wheel_bearing"/>
		<child link="left_wheel_shaft"/>
        <axis xyz="0.0 1 0.0" rpy="0.0 0.0 0.0"/>
        <limit effort="10000" velocity="1000"/>
        <dynamics damping="1.0" friction="1.0"/>
	</joint>

	<link name="left_wheel">
		<inertial>
			<origin xyz="0.0 0.5 0.0" rpy="0.0 0.0 0.0"/>
			<mass value="0.0"/>
			<inertia ixx="0.0" ixy="0.0" ixz="0.0" iyy="0.0" iyz="0.0" izz="0.0"/>
		</inertial>
		<visual name="left_wheel_visual">
			<origin xyz="0.0 0.5 0.0" rpy="0.0 0.0 0.0"/>
			<geometry>
				<mesh filename="package://custom_robot/meshes/Wheel.dae"/>
			</geometry>
		</visual>
		<collision name="left_wheel_collision">
			<origin xyz="0.0 0.5 0.0" rpy="0.0 0.0 0.0"/>
			<geometry>
				<cylinder radius="150" length="10.0"/>
			</geometry>
		</collision>
	</link>
	<joint name="left_wheel_joint" type="fixed">
		<origin xyz="0.0 0.0 0.0" rpy="0.0 0.0 0.0"/>
		<parent link="left_wheel_shaft"/>
		<child link="left_wheel"/>
		<limit lower="0.0" upper="0.0" effort="0.0" velocity="0.0"/>
	</joint>

	<link name="left_timing_pulley">
		<inertial>
			<origin xyz="0.0  0.20 0.0" rpy="0.0 0.0 -1.57"/>
			<mass value="0.0"/>
			<inertia ixx="0.0" ixy="0.0" ixz="0.0" iyy="0.0" iyz="0.0" izz="0.0"/>
		</inertial>
		<visual name="left_timing_pulley_visual">
			<origin xyz="0.0  0.20 0.0" rpy="0.0 0.0 -1.57"/>
			<geometry>
				<mesh filename="package://custom_robot/meshes/TimingPulley.dae"/>
			</geometry>
		</visual>
		<collision name="left_timing_pulley_collision">
			<origin xyz="0.0  0.20 0.0" rpy="0.0 0.0 -1.57"/>
			<geometry>
				<cylinder radius="0.150" length="0.010"/>
			</geometry>
		</collision>
	</link>
	<joint name="left_timing_pulley_joint" type="fixed">
		<origin xyz="0.0 0.0 0.0" rpy="0.0 0.0 0.0"/>
		<parent link="left_wheel_shaft"/>
		<child link="left_timing_pulley"/>
	</joint>

	<link name="right_timing_pulley">
		<inertial>
			<origin xyz="0.0  0.20 0.0" rpy="0.0 0.0 -1.57"/>
			<mass value="0.0"/>
			<inertia ixx="0.0" ixy="0.0" ixz="0.0" iyy="0.0" iyz="0.0" izz="0.0"/>
		</inertial>
		<visual name="right_timing_pulley_visual">
			<origin xyz="0.0  0.20 0.0" rpy="0.0 0.0 -1.57"/>
			<geometry>
				<mesh filename="package://custom_robot/meshes/TimingPulley.dae"/>
			</geometry>
		</visual>
		<collision name="right_timing_pulley_collision">
			<origin xyz="0.0  0.20 0.0" rpy="0.0 0.0 -1.57"/>
			<geometry>
				<cylinder radius="0.150" length="0.010"/>
			</geometry>
		</collision>
	</link>
	<joint name="right_timing_pulley_joint" type="fixed">
		<origin xyz="0.0 0.0 0.0" rpy="0.0 0.0 0.0"/>
		<parent link="right_wheel_shaft"/>
		<child link="right_timing_pulley"/>
	</joint>
	<link name="test_object">
		<inertial>
			<origin xyz="0.0  0.20 0.0" rpy="0.0 0.0 -1.57"/>
			<mass value="0.0"/>
			<inertia ixx="0.0" ixy="0.0" ixz="0.0" iyy="0.0" iyz="0.0" izz="0.0"/>
		</inertial>
		<visual name="test_object_visual">
			<origin xyz="0.0  0.20 0.0" rpy="0.0 0.0 -1.57"/>
			<geometry>
				<box size="0.001 0.001 0.001"/>
			</geometry>	
		</visual>
		<collision name="test_object_collision">
			<origin xyz="0.0  0.20 0.0" rpy="0.0 0.0 -1.57"/>
			<geometry>
				<box size="0.001 0.001 0.001"/>
			</geometry>
		</collision>
	</link>
	<joint name="test_object_joint" type="fixed">
		<origin xyz="0.0 0.0 0.0" rpy="0.0 0.0 0.0"/>
		<parent link="base_plate"/>
		<child link="test_object"/>
	</joint>
	<link name="hokuyo">
        <origin xyz="0.0 0.0 0.0" rpy="0.0 0.0 0.0"/>                    
        <inertial>
            <mass value="1e-5"/>
            <inertia ixx="1e-6" ixy="0.0" ixz="0.0" iyy="1e-6" iyz="0.0" izz="1e-6"/>
        </inertial>

        <visual name="hokuyo_visual">
            <!-- <origin xyz="0.0 0.0 0.0" rpy="0.0 0.0 0.0"/> -->
            <geometry>
                <mesh filename="package://custom_robot/meshes/hokuyo.dae"/>
            </geometry>
        </visual>

        <collision name="hokuyo_collision">
            <origin xyz="0.0 0.0 0.0" rpy="0.0 0.0 0.0"/>
            <geometry>
                <box size=".1 .1 .1"/> 
            </geometry>
        </collision>
    </link>
    <joint name="hokuyo_joint" type="fixed">
        <origin xyz="0.15 0.0 .1" rpy="0.0 0.0 0.0"/>
        <parent link="base_plate"/>
        <child link="hokuyo"/>
        <axis xyz="0.0 1 0.0"/>
    </joint>
	

</robot>
